<?xml version="1.0"?>
<robot xmlns:xacro="http://www.ros.org/wiki/xacro">

    <xacro:include filename="inertial_macros.xacro"/>
    


    <!-- ___________________ materials ___________________ -->

     <material name="white">
        <color rgba="1 1 1 1"/>
    </material>

    <material name="grey">
        <color rgba="0.7 0.7 0.7 1"/>
    </material>

    <material name="green">
        <color rgba="0.7 0.6 0.0 1"/>
    </material>

    <material name="red">
        <color rgba="0.6 0.0 0.0 1"/>
    </material>

    <material name="blue">
        <color rgba="0.0 0.0 0.6 1"/>
    </material>
    


    <!-- ___________________ links ___________________ -->

    <link name="base_link">
        <visual>
            <geometry>
                <box size="0.5 0.4 0.2"/>
            </geometry>
            <origin xyz="0.0 0.0 0.1" rpy="0.0 0.0 0.0"/>
            <material name="white"/>
        </visual>
        <collision>
            <geometry>
                <box size="0.5 0.4 0.2"/>
            </geometry>
            <origin xyz="0.0 0.0 0.1" rpy="0.0 0.0 0.0"/>
        </collision>
        <xacro:inertial_box mass="0.5" x="0.3" y="0.3" z="0.15">
            <origin xyz="0 0 0.1" rpy="0 0 0"/>
        </xacro:inertial_box>
    </link>

    <link name="lidar">
        <visual>
            <geometry>
                <cylinder radius="0.1" length="0.05"/>
            </geometry>
            <origin xyz="0.0 0.0 0.0" rpy="0.0 0.0 0.0"/>
            <material name="red"/>
        </visual>
        <collision>
            <geometry>
                <cylinder radius="0.1" length="0.05"/>
            </geometry>
            <origin xyz="0.0 0.0 0.0" rpy="0.0 0.0 0.0"/>
        </collision>
        <xacro:inertial_cylinder mass="0.1" length="0.04" radius="0.05">
            <origin xyz="0 0 0" rpy="0 0 0"/>
        </xacro:inertial_cylinder>
    </link>

    <link name="back_right_wheel">
        <visual>
            <geometry>
                <cylinder radius="0.05" length="0.03"/>
            </geometry>
            <origin xyz="0.0 0.0 0.0" rpy="0.0 0.0 0.0"/>
            <material name="blue"/>
        </visual>
        <collision>
            <geometry>
                <cylinder radius="0.05" length="0.03"/>
            </geometry>
            <origin xyz="0.0 0.0 0.0" rpy="0.0 0.0 0.0"/>
        </collision>
        <xacro:inertial_cylinder mass="0.1" length="0.04" radius="0.05">
            <origin xyz="0 0 0" rpy="0 0 0"/>
        </xacro:inertial_cylinder>
    </link>

    <link name="back_left_wheel">
        <visual>
            <geometry>
                <cylinder radius="0.05" length="0.03"/>
            </geometry>
            <origin xyz="0.0 0.0 0.0" rpy="0.0 0.0 0.0"/>
            <material name="blue"/>
        </visual>
        <collision>
            <geometry>
                <cylinder radius="0.05" length="0.03"/>
            </geometry>
            <origin xyz="0.0 0.0 0.0" rpy="0.0 0.0 0.0"/>
        </collision>
        <xacro:inertial_cylinder mass="0.1" length="0.04" radius="0.05">
            <origin xyz="0 0 0" rpy="0 0 0"/>
        </xacro:inertial_cylinder>
    </link>

    <link name="front_left_wheel">
        <visual>
            <geometry>
                <cylinder radius="0.05" length="0.03"/>
            </geometry>
            <origin xyz="0.0 0.0 0.0" rpy="0.0 0.0 0.0"/>
            <material name="blue"/>
        </visual>
        <collision>
            <geometry>
                <cylinder radius="0.05" length="0.03"/>
            </geometry>
            <origin xyz="0.0 0.0 0.0" rpy="0.0 0.0 0.0"/>
        </collision>
        <xacro:inertial_cylinder mass="0.1" length="0.04" radius="0.05">
            <origin xyz="0 0 0" rpy="0 0 0"/>
        </xacro:inertial_cylinder>
    </link>

    <link name="front_right_wheel">
        <visual>
            <geometry>
                <cylinder radius="0.05" length="0.03"/>
            </geometry>
            <origin xyz="0.0 0.0 0.0" rpy="0.0 0.0 0.0"/>
            <material name="blue"/>
        </visual>
        <collision>
            <geometry>
                <cylinder radius="0.05" length="0.03"/>
            </geometry>
            <origin xyz="0.0 0.0 0.0" rpy="0.0 0.0 0.0"/>
        </collision>
        <xacro:inertial_cylinder mass="0.1" length="0.04" radius="0.05">
            <origin xyz="0 0 0" rpy="0 0 0"/>
        </xacro:inertial_cylinder>
    </link>



    <!-- ___________________ joints ___________________ -->

    <joint name="lidar_joint" type="fixed">
            <parent link="base_link"/>
            <child link="lidar"/>
            <origin xyz="0.0 0.0 0.225" rpy="0.0 0.0 0.0"/>
    </joint>

    <joint name="back_left_wheel_joint" type="continuous">
            <parent link="base_link"/>
            <child link="back_left_wheel"/>
            <origin xyz="-0.125 0.215 0.0" rpy="-${pi/2} 0.0 0.0"/>
             <axis xyz="0.0 0.0 1"/>
    </joint>

    <joint name="back_right_wheel_joint" type="continuous">
            <parent link="base_link"/>
            <child link="back_right_wheel"/>
            <origin xyz="-0.125 -0.215 0.0" rpy="${pi/2} 0.0 0.0"/>
             <axis xyz="0.0 0.0 1"/>
    </joint>

    <joint name="front_left_wheel_joint" type="continuous">
            <parent link="base_link"/>
            <child link="front_left_wheel"/>
            <origin xyz="0.125 0.215 0.0" rpy="-${pi/2} 0.0 0.0"/>
             <axis xyz="0.0 0.0 1"/>
    </joint>

    <joint name="front_right_wheel_joint" type="continuous">
            <parent link="base_link"/>
            <child link="front_right_wheel"/>
            <origin xyz="0.125 -0.215 0.0" rpy="${pi/2} 0.0 0.0"/>
             <axis xyz="0.0 0.0 1"/>
    </joint>
        
</robot>